<robot name="cyberglove">
  <link name="cyberglove_forearm">
    <inertial>
      <mass value="3.0" />
      <origin xyz="0 0 0.090" /> 
      <inertia  ixx="1.0" ixy="0.0"  ixz="0.0"  iyy="100.0"  iyz="0.0"  izz="1.0" />
    </inertial>
    <visual>
      <origin xyz="0 0 0" rpy="0 0 0" />
      <geometry name="cyberglove_forearm_geom">
        <cylinder radius="0.06" length="0.180"/>
      </geometry>
    </visual>
    <collision>
      <origin xyz="0 0 0" rpy="0 0 0" />
      <geometry name="cyberglove_forearm_collision">
        <cylinder radius="0.06" length="0.180"/>
      </geometry>
      <origin xyz="1 0 0" rpy="0 0 0 " />
      <geometry name="cyberglove_forearm_collision_geom">
        <box size="0.05 0.05 0.10" />
      </geometry>
    </collision>
  </link>

  <!-- FIRST FINGER-->

  <link name="ffproximal">
    <inertial>
      <mass value="0.008" />
      <origin xyz="0 0.010 0.233" /> 
      <inertia  ixx="1.0" ixy="0.0"  ixz="0.0"  iyy="100.0"  iyz="0.0"
      izz="1.0" />
    </inertial>
    <visual>
      <origin xyz="0 0 0.0225" rpy="0 0 0" />
      <geometry name="ffproximal_geom">
        <cylinder radius="0.005" length="0.045"/>
      </geometry>
    </visual>
    <collision>
      <origin xyz="0 0 0" rpy="0 0 0 " />
      <geometry name="ffproximal_collision_geom">
        <box size="0.05 0.05 0.10" />
      </geometry>
    </collision>
  </link>

  <link name="ffmiddle">
    <inertial>
      <origin xyz="0 0 0.045" rpy="0 0 0" />
      <mass value="0.008" />
      <inertia  ixx="1.0" ixy="0.0"  ixz="0.0"  iyy="100.0"  iyz="0.0"
      izz="1.0" />
    </inertial>
    <visual>
      <origin xyz="0 0 0.0125" rpy="0 0 0" />
      <geometry name="ffmiddle_geom">
        <cylinder radius="0.005" length="0.025"/>
      </geometry>
    </visual>
    <collision>
      <origin xyz="0 0 0" rpy="0 0 0" />
      <geometry name="ffmiddle_collision_geom">
        <box size="0.05 0.05 0.10" />
      </geometry>
    </collision>
  </link>

  <link name="ffdistal">
    <inertial>
      <mass value="0.008" />
      <origin xyz="0 0 0.025" /> 
      <inertia  ixx="1.0" ixy="0.0"  ixz="0.0"  iyy="100.0"  iyz="0.0"
      izz="1.0" />
    </inertial>
    <visual>
      <origin xyz="0 0 0.013" rpy="0 0 0" />
      <geometry name="ffdistal_geom">
        <cylinder radius="0.005" length="0.026"/>
      </geometry>
    </visual>
    <collision>
      <origin xyz="0 0 0" rpy="0 0 0 " />
      <geometry name="ffdistal_collision_geom">
        <box size="0.05 0.05 0.10" />
      </geometry>
    </collision>
  </link>

 <!--------------------------------
|             JOINTS               |
 --------------------------------->   
<!--
 <joint name="attachment" type="continuous">
   <parent link="world"/>
   <child link="cyberglove_forearm"/>
   <origin xyz="5 0 0" rpy="0 0 3.14" />
   <axis xyz="0 1 0" />
 </joint>
 -->
  <joint name="G_IndexPIJ" type="revolute">
    <parent link="cyberglove_forearm"/>
    <child link="ffproximal"/>   
    <origin xyz="0 0.010 0.233" rpy="0 0 0" />
    <axis xyz="0 0 1" />
    <limit lower="0" upper="1.5707963267948966"
    effort="10" velocity="1.0"/>
  </joint>

  <joint name="G_IndexMPJ" type="revolute">
    <parent link="ffproximal"/>
    <child link="ffmiddle"/>
    <origin xyz="0 0 0.045" rpy="0 0 0" />
    <axis xyz="1 0 0" />
    <limit lower="0" upper="1.5707963267948966" effort="10"
    velocity="1.0"/>
  </joint>

  <joint name="G_IndexDIJ" type="revolute">
    <parent link="ffmiddle"/>
    <child link="ffdistal"/>
    <origin xyz="0 0 0.025" rpy="0 0 0" />
    <axis xyz="1 0 0" />
    <limit lower="0" upper="1.5707963267948966" effort="10"
    velocity="1.0"/>
  </joint>

</robot>
