<?xml version="1.0" ?>
<!-- =================================================================================== -->
<!-- |    This document was autogenerated by xacro from xacro/sr_arm_muscle.urdf.xacro | -->
<!-- |    EDITING THIS FILE BY HAND IS NOT RECOMMENDED                                 | -->
<!-- =================================================================================== -->
<robot name="sr_arm_muscle" xmlns:controller="http://playerstage.sourceforge.net/gazebo/xmlschema/#controller" xmlns:interface="http://playerstage.sourceforge.net/gazebo/xmlschema/#interface" xmlns:sensor="http://playerstage.sourceforge.net/gazebo/xmlschema/#sensor" xmlns:xacro="http://ros.org/wiki/xacro">
  <material name="Blue">
    <color rgba="0.0 0.0 0.8 1.0"/>
  </material>
  <material name="Green">
    <color rgba="0.0 0.8 0.0 1.0"/>
  </material>
  <material name="Grey">
    <color rgba="0.2 0.2 0.2 1.0"/>
  </material>
  <material name="LightGrey">
    <color rgba="0.6 0.6 0.6 1.0"/>
  </material>
  <material name="Red">
    <color rgba="0.8 0.0 0.0 1.0"/>
  </material>
  <material name="White">
    <color rgba="1.0 1.0 1.0 1.0"/>
  </material>
  <gazebo>
    <controller:gazebo_ros_controller_manager name="gazebo_ros_controller_manager" plugin="libgazebo_ros_controller_manager.so">
      <alwaysOn>true</alwaysOn>
      <updateRate>1000.0</updateRate>
    </controller:gazebo_ros_controller_manager>
  </gazebo>
  <link name="world"/>
  <link name="shadowarm_base">
    <inertial>
      <origin rpy="0 0 0" xyz="0 0 0"/>
      <mass value="0.4"/>
      <inertia ixx="1.0" ixy="0.0" ixz="0.0" iyy="0.0" iyz="0.0" izz="0.0"/>
    </inertial>
    <visual>
      <origin rpy="1.57079632679 0 0" xyz="0 0 0.005"/>
      <geometry name="shadowarm_base_visual">
        <mesh filename="package://sr_hand/model/meshes/arm/arm_base.mesh" scale="0.001 0.001 0.001"/>
      </geometry>
      <material name="LightGrey"/>
    </visual>
    <collision>
      <origin rpy="0 0 0" xyz="0 0 0.005"/>
      <geometry name="shadowarm_base_collision">
        <box size="0.03 0.03 0.01"/>
      </geometry>
    </collision>
  </link>
  <gazebo reference="shadowarm_base">
    <material>Gazebo/Grey</material>
    <selfCollide>true</selfCollide>
  </gazebo>
  <joint name="base_fix" type="fixed">
    <parent link="world"/>
    <child link="shadowarm_base"/>
    <origin rpy="0 0 0" xyz="0 0 0"/>
  </joint>
  <link name="shadowarm_trunk">
    <inertial>
      <origin rpy="0 0 0" xyz="0 0 0.27025"/>
      <mass value="5"/>
      <inertia ixx="1.0" ixy="0.0" ixz="0.0" iyy="0.0" iyz="0.0" izz="0.0"/>
    </inertial>
    <visual>
      <origin rpy="1.57079632679 3.14159265359 1.57079632679" xyz="0 0 0.0165"/>
      <geometry name="shadowarm_trunk_visual">
        <mesh filename="package://sr_hand/model/meshes/arm/arm_trunk.mesh" scale="0.001 0.001 0.001"/>
      </geometry>
      <material name="Grey"/>
    </visual>
    <collision>
      <origin rpy="0 0 0" xyz="0 0 0.27025"/>
      <geometry name="shadowarm_trunk_collision">
        <box size="0.03 0.03 0.5405"/>
      </geometry>
    </collision>
  </link>
  <gazebo reference="shadowarm_trunk">
    <material>Gazebo/Grey</material>
    <selfCollide>true</selfCollide>
  </gazebo>
  <joint name="ShoulderJRotate" type="revolute">
    <parent link="shadowarm_base"/>
    <child link="shadowarm_trunk"/>
    <origin rpy="0 0 0" xyz="0 0 0.01"/>
    <axis xyz="0 0 1"/>
    <limit effort="10" lower="-0.785398163397" upper="1.57079632679" velocity="1.0"/>
    <dynamics damping="200.5"/>
  </joint>
  <transmission name="trunk_rotation_transmission" type="pr2_mechanism_model/SimpleTransmission">
    <actuator name="trunk_rotation"/>
    <joint name="ShoulderJRotate"/>
    <mechanicalReduction>1</mechanicalReduction>
    <motorTorqueConstant>1</motorTorqueConstant>
    <pulsesPerRevolution>90000</pulsesPerRevolution>
  </transmission>
  <link name="shadowarm_upperarm">
    <inertial>
      <origin rpy="0 0 0" xyz="0 -0.067 -0.1845"/>
      <mass value="2"/>
      <inertia ixx="1.0" ixy="0.0" ixz="0.0" iyy="0.0" iyz="0.0" izz="0.0"/>
    </inertial>
    <visual>
      <origin rpy="0 0 -1.57079632679" xyz="0 0.067 0"/>
      <geometry name="shadowarm_upperarm_visual">
        <mesh filename="package://sr_hand/model/meshes/arm/upper_arm.mesh" scale="0.001 0.001 0.001"/>
      </geometry>
      <material name="Grey"/>
    </visual>
    <collision>
      <origin rpy="0 -3.14159265359 0" xyz="0 0 0.1845"/>
      <geometry name="shadowarm_upperarm_collision">
        <box size="0.03 0.03 0.369"/>
      </geometry>
    </collision>
  </link>
  <gazebo reference="shadowarm_upperarm">
    <material>Gazebo/Grey</material>
    <selfCollide>true</selfCollide>
  </gazebo>
  <joint name="ShoulderJSwing" type="revolute">
    <parent link="shadowarm_trunk"/>
    <child link="shadowarm_upperarm"/>
    <origin rpy="0 -3.14159265359 0" xyz="0 -0.134 0.5405"/>
    <axis xyz="0 -1 0"/>
    <limit effort="10" lower="0" upper="1.57079632679" velocity="1.0"/>
    <dynamics damping="50.5"/>
  </joint>
  <transmission name="shoulder_rotation_transmission" type="pr2_mechanism_model/SimpleTransmission">
    <actuator name="shoulder_rotation"/>
    <joint name="ShoulderJSwing"/>
    <mechanicalReduction>1</mechanicalReduction>
    <motorTorqueConstant>1</motorTorqueConstant>
    <pulsesPerRevolution>90000</pulsesPerRevolution>
  </transmission>
  <link name="shadowarm_lowerarm">
    <inertial>
      <origin rpy="0 0 0" xyz="0.08 0 0.0655"/>
      <mass value="1.7"/>
      <inertia ixx="1.0" ixy="0.0" ixz="0.0" iyy="0.0" iyz="0.0" izz="0.0"/>
    </inertial>
    <visual>
      <origin rpy="3.14159265359 -1.07079632679 0" xyz="0.03 0 0.036"/>
      <geometry name="shadowarm_lowerarm_visual">
        <mesh filename="package://sr_hand/model/meshes/arm/elbow_flex.mesh" scale="0.001 0.001 0.001"/>
      </geometry>
      <material name="Grey"/>
    </visual>
    <collision>
      <origin rpy="0 0 0" xyz="0.08 0 0.0655"/>
      <geometry name="shadowarm_lowerarm_collision">
        <box size="0.03 0.03 0.131"/>
      </geometry>
    </collision>
  </link>
  <gazebo reference="shadowarm_lowerarm">
    <material>Gazebo/Grey</material>
    <selfCollide>true</selfCollide>
  </gazebo>
  <joint name="ElbowJSwing" type="revolute">
    <parent link="shadowarm_upperarm"/>
    <child link="shadowarm_lowerarm"/>
    <origin rpy="0 0 0" xyz="0 0 0.369"/>
    <axis xyz="0 -1 0"/>
    <limit effort="10" lower="0" upper="2.09439510239" velocity="1.0"/>
    <dynamics damping="50.5"/>
  </joint>
  <transmission name="elbow_abduction_transmission" type="pr2_mechanism_model/SimpleTransmission">
    <actuator name="elbow_abduction"/>
    <joint name="ElbowJSwing"/>
    <mechanicalReduction>1</mechanicalReduction>
    <motorTorqueConstant>1</motorTorqueConstant>
    <pulsesPerRevolution>90000</pulsesPerRevolution>
  </transmission>
  <link name="shadowarm_handsupport_muscle">
    <inertial>
      <origin rpy="0 0 0" xyz="0 0 0"/>
      <mass value="0.75"/>
      <inertia ixx="1.0" ixy="0.0" ixz="0.0" iyy="0.0" iyz="0.0" izz="0.0"/>
    </inertial>
    <visual>
      <origin rpy="1.57079632679 0 0" xyz="0 0 -0.04"/>
      <geometry name="shadowarm_handsupport_visual">
        <mesh filename="package://sr_hand/model/meshes/arm/elbow_rotate_muscle.mesh" scale="0.001 0.001 0.001"/>
      </geometry>
      <material name="LightGrey"/>
    </visual>
    <collision>
      <origin rpy="0 0 0" xyz="0 0 0"/>
      <geometry name="shadowarm_handsupport_collision">
        <cylinder length="0.001" radius="0.06"/>
      </geometry>
    </collision>
  </link>
  <gazebo reference="shadowarm_handsupport_muscle">
    <material>Gazebo/Grey</material>
    <selfCollide>true</selfCollide>
  </gazebo>
  <joint name="ElbowJRotate" type="revolute">
    <parent link="shadowarm_lowerarm"/>
    <child link="shadowarm_handsupport_muscle"/>
    <origin rpy="0 0 0" xyz="0.08 0 0.131"/>
    <axis xyz="0 0 -1"/>
    <limit effort="10" lower="-1.57079632679" upper="1.57079632679" velocity="1.0"/>
    <dynamics damping="10.5"/>
  </joint>
  <transmission name="forearm_rotation_transmission" type="pr2_mechanism_model/SimpleTransmission">
    <actuator name="forearm_rotation"/>
    <joint name="ElbowJRotate"/>
    <mechanicalReduction>1</mechanicalReduction>
    <motorTorqueConstant>1</motorTorqueConstant>
    <pulsesPerRevolution>90000</pulsesPerRevolution>
  </transmission>
</robot>
