<robot xmlns:xacro="http://ros.org/wiki/xacro"
       xmlns:sensor="http://playerstage.sourceforge.net/gazebo/xmlschema/#sensor"
       xmlns:controller="http://playerstage.sourceforge.net/gazebo/xmlschema/#controller"
       xmlns:joint="http://playerstage.sourceforge.net/gazebo/xmlschema/#slider"
       xmlns:interface="http://playerstage.sourceforge.net/gazebo/xmlschema/#interface"
       xmlns:body="http://playerstage.sourceforge.net/gazebo/xmlschema/#body"
       xmlns:geom="http://playerstage.sourceforge.net/gazebo/xmlschema/#geom">

  <xacro:include filename="$(find sr_description)/hand/xacro/finger/distal/distal.transmission.xacro" />
  
  <!-- muscle is true for muscle hand or false for motor hand -->
  <!-- bio is true for biotac finger or false for standard finger -->
  <!-- ubi is true for ubi finger or false for standard finger -->
  <!-- eli is true for ellipsoid fingertip or false for standard finger -->
  <!-- prefix can be anything but usually is "r_" or  "l_" for right and left hands distinction -->
  <!-- link_prefix prepends fingername to the link names -->
  <!-- joint_prefix prepends fingername to the joint names -->
  <!-- parent is the parent link for the joint -->
  <xacro:macro name="distal" params="muscle bio ubi eli prefix link_prefix joint_prefix parent">
    <link name="${prefix}${link_prefix}distal">
      <inertial>
        <mass value="0.010" />
        <origin xyz="0 0 0.013" />
        <inertia  ixx="0.1" ixy="0.0"  ixz="0.0"  iyy="0.1"  iyz="0.0"
        izz="0.0" />
      </inertial>
      <visual>
        <origin xyz="0 0 0" rpy="0 0 0" />
        <geometry name="${prefix}${link_prefix}distal_visual">
          <!-- Ubi distal -->
          <xacro:if value="${ubi}">
            <mesh filename="package://sr_description/hand/model/F1.dae" scale="0.001 0.001 0.001" />
          </xacro:if> 
          <!-- Check for ellispoid distal -->
          <xacro:unless value="${ubi}">
            <!-- Ellispoid distal  -->
            <xacro:if value="${eli}">
							<mesh filename="package://sr_description/hand/model/ellipsoids/distal_ellipsoid_visual.dae" scale="0.001 0.001 0.001" />
            </xacro:if> 
            <!-- Check for biotac distal -->
            <xacro:unless value="${eli}">
              <!-- biotac distal  -->
              <xacro:if value="${bio}">
                 <mesh filename="package://sr_description/hand/model/F1.dae" scale="0.001 0.001 0.001" />
              </xacro:if> 
              <!-- Standard distal  -->
              <xacro:unless value="${bio}">
                 <mesh filename="package://sr_description/hand/model/F1.dae" scale="0.001 0.001 0.001" />
              </xacro:unless> 
            </xacro:unless> 
          </xacro:unless> 
        </geometry>
        <material name="Grey" />
      </visual>
      <collision>
        <origin xyz="0 0 0" rpy="0 0 0" />
        <geometry name="${prefix}${link_prefix}distal_collision_geom">
            <!-- Ubi distal -->
          <xacro:if value="${ubi}">
            <mesh filename="package://sr_description/hand/model/F1.dae" scale="0.001 0.001 0.001" />
          </xacro:if> 
          <!-- Check for ellispoid distal -->
          <xacro:unless value="${ubi}">
            <!-- Ellispoid distal  -->
            <xacro:if value="${eli}">
               <mesh filename="package://sr_description/hand/model/ellipsoids/distal_ellipsoid.dae" scale="0.001 0.001 0.001" />
            </xacro:if> 
            <!-- Check for biotac distal -->
            <xacro:unless value="${eli}">
              <!-- biotac distal  -->
              <xacro:if value="${bio}">
                 <mesh filename="package://sr_description/hand/model/F1.dae" scale="0.001 0.001 0.001" />
              </xacro:if> 
              <!-- Standard distal  -->
              <xacro:unless value="${bio}">
                 <mesh filename="package://sr_description/hand/model/F1.dae" scale="0.001 0.001 0.001" />
              </xacro:unless> 
            </xacro:unless> 
          </xacro:unless> 
        </geometry>
      </collision>
    </link>
    <xacro:unless value="${bio}">
    <joint name="${prefix}${joint_prefix}J1" type="revolute">
      <parent link="${parent}"/>
      <child link="${prefix}${link_prefix}distal"/>
      <origin xyz="0 0 0.025" rpy="0 0 0" />
      <axis xyz="1 0 0" />
       <!-- biotac fixed distal joint -->
      <xacro:if value="${bio}">
        <limit lower="${20/180*M_PI}" upper="${20/180*M_PI}" effort="10"
          velocity="1.0" />
      </xacro:if> 
      <!-- standard distal joint -->
      <xacro:unless value="${bio}">
          <limit lower="0" upper="${M_PI/2}" effort="10"
          velocity="1.0" />
      </xacro:unless>  
      <dynamics damping="50.5"/>
    </joint>       
            
    <link name="${prefix}${link_prefix}tip">
			<inertial>
				<mass value="0.001" />
				<inertia  ixx="0.0" ixy="0.0"  ixz="0.0"  iyy="0.0"  iyz="0.0" izz="0.0" />
  		</inertial>
    </link>
    <joint name="${prefix}${joint_prefix}tip" type="fixed">
      <parent link="${prefix}${link_prefix}distal"/>
      <child link="${prefix}${link_prefix}tip"/>
      <origin xyz="0 0 0.026" rpy="0 0 0" />
    </joint>
    </xacro:unless>
    <!-- extensions -->
    <!--   <xacro:distal_transmission muscletrans="${muscle}" prefix="${prefix}" /> -->
    <xacro:distal_gazebo prefix="${prefix}" />
  </xacro:macro>

</robot>
