<robot xmlns:xacro="http://ros.org/wiki/xacro"
		 xmlns:sensor="http://playerstage.sourceforge.net/gazebo/xmlschema/#sensor"
       xmlns:controller="http://playerstage.sourceforge.net/gazebo/xmlschema/#controller"
       xmlns:joint="http://playerstage.sourceforge.net/gazebo/xmlschema/#slider"
       xmlns:interface="http://playerstage.sourceforge.net/gazebo/xmlschema/#interface"
       xmlns:body="http://playerstage.sourceforge.net/gazebo/xmlschema/#body"
       xmlns:geom="http://playerstage.sourceforge.net/gazebo/xmlschema/#geom">

  <xacro:include filename="$(find sr_description)/hand/xacro/palm/palm.gazebo.xacro" />
  <xacro:include filename="$(find sr_description)/hand/xacro/palm/palm.transmission.xacro" />
  
  <!-- muscle is true for muscle hand or false for motor hand -->
  <!-- prefix can be anything but usually is "r_" or  "l_" for right and left hands distinction -->
  <!-- reflect is either 1 (for right hand) or -1 (for left hand) -->
  <!-- parent is the parent link for the joint -->
  <xacro:macro name="palm" params="muscle prefix reflect parent">
    <link name="${prefix}palm">
      <inertial>
        <origin xyz="0 0 0.035" rpy="0 0 0" />
        <mass value="0.3" />
        <inertia  ixx="0.5" ixy="0.0"  ixz="0.0"  iyy="0.5"  iyz="0.0"	izz="0.3" />
      </inertial>

      <visual>
        <origin xyz="0 0 0" rpy="0 0 0" />
        <geometry name="${prefix}palm_visual">
          <mesh filename="package://sr_description/hand/model/palm.dae" 
					 scale="${reflect*0.001} 0.001 0.001" />
        </geometry>
        <material name="Grey"/>
      </visual>

      <collision>
        <origin xyz="${reflect*0.005} 0 0.035" rpy="0 0 0" />
        <geometry name="${prefix}palm_collision_geom">
          <box size="0.05 0.02 0.07" />
        </geometry>
      </collision>
    </link>

    <joint name="${prefix}WRJ1" type="revolute">
      <parent link="${parent}"/>
      <child link="${prefix}palm"/>
      <origin xyz="0 0 0.034" rpy="0 0 0" />
      <axis xyz="1 0 0" />
      <limit lower="${-40/180*M_PI}" upper="${28/180*M_PI}"
      effort="5" velocity="1.0"/>
      <dynamics damping="100.5"/>
    </joint>
    
    <!-- extensions -->
    <xacro:shadowhand_palm_transmission muscle="${muscle}" prefix="${prefix}" />
    <xacro:shadowhand_palm_gazebo prefix="${prefix}" />
  </xacro:macro>

</robot>
