<?xml version="1.0" ?>
<!-- =================================================================================== -->
<!-- |    This document was autogenerated by xacro from sr_edc.urdf.xacro              | -->
<!-- |    EDITING THIS FILE BY HAND IS NOT RECOMMENDED                                 | -->
<!-- =================================================================================== -->
<robot name="SRH" xmlns:controller="http://playerstage.sourceforge.net/gazebo/xmlschema/#controller" xmlns:interface="http://playerstage.sourceforge.net/gazebo/xmlschema/#interface" xmlns:joint="http://playerstage.sourceforge.net/gazebo/xmlschema/#slider" xmlns:sensor="http://playerstage.sourceforge.net/gazebo/xmlschema/#sensor">
  <!-- FIXME: all the limits are not valid -->
  <!-- FIXME: all the limits are not valid -->
  <link name="world"/>
  <joint name="WRJ2_joint" type="revolute">
    <parent link="world"/>
    <child link="sr_wrist_dummy_link"/>
    <origin rpy="0 0 0" xyz="0 0 0"/>
    <axis xyz="0 1 0"/>
    <limit effort="100.0" lower="-0.524" upper="0.175" velocity="0.5"/>
  </joint>
  <link name="sr_wrist_dummy_link">
    </link>
  <joint name="WRJ1_joint" type="revolute">
    <parent link="sr_wrist_dummy_link"/>
    <child link="sr_hand_palm_link"/>
    <origin rpy="0 0 0" xyz="0 0 0.034"/>
    <axis xyz="1 0 0"/>
    <limit effort="100.0" lower="-0.786" upper="0.611" velocity="0.5"/>
  </joint>
  <link name="sr_hand_palm_link">

    </link>
  <!-- ........................................ -->
  <joint name="FFJ4_joint" type="revolute">
    <parent link="sr_hand_palm_link"/>
    <child link="sr_hand_ff4_link"/>
    <origin rpy="0 0 0" xyz="0.033 0 0.095"/>
    <axis xyz="0 -1 0"/>
    <limit effort="100.0" lower="-0.436" upper="0.436" velocity="1.0"/>
  </joint>
  <link name="sr_hand_ff4_link">

    </link>
  <joint name="FFJ3_joint" type="revolute">
    <parent link="sr_hand_ff4_link"/>
    <child link="sr_hand_ff3_link"/>
    <origin rpy="0 0 0" xyz="0 0 0"/>
    <axis xyz="1 0 0"/>
    <limit effort="100.0" lower="0.0" upper="1.571" velocity="1.0"/>
  </joint>
  <link name="sr_hand_ff3_link">

    </link>
  <!-- ........................................ -->
  <transmission name="WRJ1_trans" type="pr2_mechanism_model/SimpleTransmission">
    <actuator name="WRJ1"/>
    <joint name="WRJ1_joint"/>
    <mechanicalReduction>1.0</mechanicalReduction>
  </transmission>
  <transmission name="WRJ2_trans" type="pr2_mechanism_model/SimpleTransmission">
    <actuator name="WRJ2"/>
    <joint name="WRJ2_joint"/>
    <mechanicalReduction>1.0</mechanicalReduction>
  </transmission>
  <transmission name="FFJ3_trans" type="pr2_mechanism_model/SimpleTransmission">
    <actuator name="FFJ3"/>
    <joint name="FFJ3_joint"/>
    <mechanicalReduction>1.0</mechanicalReduction>
  </transmission>
  <transmission name="FFJ4_trans" type="pr2_mechanism_model/SimpleTransmission">
    <actuator name="FFJ4"/>
    <joint name="FFJ4_joint"/>
    <mechanicalReduction>1.0</mechanicalReduction>
  </transmission>
</robot>
