<robot xmlns:xacro="http://ros.org/wiki/xacro">

  <include filename="$(find sr_hand)/model/hand_urdf/thumb/thproximal.transmission.xacro" />

  <xacro:macro name="thproximal" params="parent">
  
    <link name="thproximal">
      <inertial>
	<mass value="0.016" />
	<origin xyz="0 0 0" rpy="0 0 0"/> 
	<inertia  ixx="1.0" ixy="0.0"  ixz="0.0"  iyy="0.0"  iyz="0.0"
	izz="0.0" />
      </inertial>
      <visual>
	<origin xyz="0 0 0" rpy="0 0 0" />
	<geometry name="thproximal_visual">
      <mesh filename="package://sr_hand/model/meshes/TH3_z.mesh" scale="0.001 0.001 0.001" />
      </geometry>
      <material name="shadow_thproximal_material">
	  <color rgba="0.2 0.2 0.2 1.0"/>
	</material>
      </visual>
      <collision>
	<origin xyz="0 0 0.02" rpy="0 0 0" />
	<geometry name="thproximal_collision_geom">
	  <box size="0.005 0.005 0.02" />
	</geometry>
      </collision>
    </link>
    <gazebo reference="thproximal">
      <material>Gazebo/Grey</material>
    </gazebo>
    
    <joint name="THJ4" type="revolute">
      <parent link="${parent}"/>
      <child link="thproximal"/>
      <origin xyz="0 0 0" rpy="0 0 0" />
      <axis xyz="1 0 0" />
      <limit lower="0" upper="1.309" effort="10"
      velocity="1.0" />
      <dynamics damping="50.5"/>
    </joint>

    <xacro:thproximal_transmission />
  
  </xacro:macro>
  
</robot>
