<?xml version="1.0" ?>
<!-- =================================================================================== -->
<!-- |    This document was autogenerated by xacro from /home/liyi/sr_remap_ws/src/sr-ros-interface/sr_description/robots/shadowhand_motor.urdf.xacro | -->
<!-- |    EDITING THIS FILE BY HAND IS NOT RECOMMENDED                                 | -->
<!-- =================================================================================== -->
<robot name="shadowhand_motor" xmlns:body="http://playerstage.sourceforge.net/gazebo/xmlschema/#body" xmlns:controller="http://playerstage.sourceforge.net/gazebo/xmlschema/#controller" xmlns:geom="http://playerstage.sourceforge.net/gazebo/xmlschema/#geom" xmlns:interface="http://playerstage.sourceforge.net/gazebo/xmlschema/#interface" xmlns:joint="http://playerstage.sourceforge.net/gazebo/xmlschema/#slider" xmlns:sensor="http://playerstage.sourceforge.net/gazebo/xmlschema/#sensor" xmlns:xacro="http://ros.org/wiki/xacro">
  <material name="Blue">
    <color rgba="0.0 0.0 0.8 1.0"/>
  </material>
  <material name="Green">
    <color rgba="0.0 0.8 0.0 1.0"/>
  </material>
  <material name="BiotacGreen">
    <color rgba="0.31 0.85 0.42 1.0"/>
  </material>
  <material name="Grey">
    <color rgba="0.2 0.2 0.2 1.0"/>
  </material>
  <material name="LightGrey">
    <color rgba="0.6 0.6 0.6 1.0"/>
  </material>
  <material name="Red">
    <color rgba="0.8 0.0 0.0 1.0"/>
  </material>
  <material name="White">
    <color rgba="1.0 1.0 1.0 1.0"/>
  </material>
  <gazebo>
    <plugin filename="libsr_gazebo_ros_controller_manager.so" name="sr_gazebo_ros_controller_manager">
      <alwaysOn>true</alwaysOn>
      <updateRate>1400.0</updateRate>
    </plugin>
  </gazebo>
  <link name="forearm">
    <inertial>
      <origin rpy="0 0 0" xyz="0 0 0.09"/>
      <mass value="3.0"/>
      <inertia ixx="1.0" ixy="0.0" ixz="0.0" iyy="1.0" iyz="0.0" izz="1.0"/>
    </inertial>
    <visual>
      <origin rpy="0 0 0" xyz="0 0 0"/>
      <geometry name="shadow_forearm_geom">
        <mesh filename="package://sr_description/hand/model/forearm.dae" scale="0.001 0.001 0.001"/>
      </geometry>
      <material name="Grey"/>
    </visual>
    <collision>
      <origin rpy="0 0 0" xyz="0 0 0.09"/>
      <geometry name="shadow_forearm_collision">
        <cylinder length="0.180" radius="0.06"/>
      </geometry>
    </collision>
  </link>
  <gazebo reference="forearm">
    <material>Gazebo/Grey</material>
    <selfCollide>false</selfCollide>
  </gazebo>
  <link name="wrist">
    <inertial>
      <origin rpy="0 0 0" xyz="0 0.0 0.0"/>
      <!--<insert_block name="origin" />-->
      <mass value="0.1"/>
      <inertia ixx="0.120" ixy="0.0" ixz="0.0" iyy="0.148" iyz="0.0" izz="0.0438"/>
    </inertial>
    <visual>
      <origin rpy="0 0 0" xyz="0 0 0"/>
      <geometry name="wrist_visual">
        <mesh filename="package://sr_description/hand/model/wrist.dae" scale="0.001 0.001 0.001"/>
      </geometry>
      <material name="LightGrey"/>
    </visual>
    <collision>
      <origin rpy="0 0 0" xyz="0 0 0"/>
      <geometry name="wrist_collision_geom">
        <box size="0.02 0.02 0.02"/>
      </geometry>
    </collision>
  </link>
  <gazebo reference="wrist">
    <material>PR2/Grey2</material>
    <selfCollide>false</selfCollide>
  </gazebo>
  <joint name="WRJ2" type="revolute">
    <parent link="forearm"/>
    <child link="wrist"/>
    <!--<origin xyz="0 -0.010 0.213" rpy="0 0 0" />-->
    <origin rpy="0 0 0" xyz="0 -0.010 0.213"/>
    <axis xyz="0 1 0"/>
    <limit effort="5" lower="-0.52359877559829882" upper="0.17453292519943295" velocity="1.0"/>
    <dynamics damping="100.5"/>
  </joint>
  <transmission name="wrist_transmission" type="sr_mechanism_model/SimpleTransmission">
    <actuator name="WRJ2"/>
    <joint name="WRJ2"/>
    <mechanicalReduction>1</mechanicalReduction>
    <motorTorqueConstant>1</motorTorqueConstant>
    <pulsesPerRevolution>90000</pulsesPerRevolution>
  </transmission>
  <link name="palm">
    <inertial>
      <origin rpy="0 0 0" xyz="0 0 0.035"/>
      <mass value="0.3"/>
      <inertia ixx="0.5" ixy="0.0" ixz="0.0" iyy="0.5" iyz="0.0" izz="0.3"/>
    </inertial>
    <visual>
      <origin rpy="0 0 0" xyz="0 0 0"/>
      <geometry name="palm_visual">
        <mesh filename="package://sr_description/hand/model/palm.dae" scale="0.001 0.001 0.001"/>
      </geometry>
      <material name="Grey"/>
    </visual>
    <collision>
      <origin rpy="0 0 0" xyz="0.005 0 0.035"/>
      <geometry name="palm_collision_geom">
        <box size="0.05 0.02 0.07"/>
      </geometry>
    </collision>
  </link>
  <gazebo reference="palm">
    <sensor name="palm_contact_sensor" type="contact">
      <update_rate>100.0</update_rate>
      <contact>
        <collision>palm_collision_geom</collision>
      </contact>
      <plugin filename="libgazebo_ros_bumper.so" name="palm_gazebo_ros_bumper_controller">
        <alwaysOn>true</alwaysOn>
        <frameName>palm</frameName>
        <updateRate>100.0</updateRate>
        <bumperTopicName>palm_bumper</bumperTopicName>
      </plugin>
    </sensor>
    <material>Gazebo/Grey</material>
  </gazebo>
  <joint name="WRJ1" type="revolute">
    <parent link="wrist"/>
    <child link="palm"/>
    <origin rpy="0 0 0" xyz="0 0 0.034"/>
    <axis xyz="1 0 0"/>
    <limit effort="5" lower="-0.7854" upper="0.5236" velocity="1.0"/>
    <dynamics damping="100.5"/>
  </joint>
  <transmission name="palm_transmission" type="sr_mechanism_model/SimpleTransmission">
    <actuator name="WRJ1"/>
    <joint name="WRJ1"/>
    <mechanicalReduction>1</mechanicalReduction>
    <motorTorqueConstant>1</motorTorqueConstant>
    <pulsesPerRevolution>90000</pulsesPerRevolution>
  </transmission>
  <link name="ffknuckle">
    <inertial>
      <origin rpy="0 0 0" xyz="0 0 0"/>
      <!--<insert_block name="origin" /> -->
      <mass value="0.008"/>
      <inertia ixx="0.0" ixy="0.0" ixz="0.0" iyy="0.1" iyz="0.0" izz="0.0"/>
    </inertial>
    <visual>
      <origin rpy="0 0 0" xyz="0 0 0.0005"/>
      <geometry name="ffknuckle_visual">
        <mesh filename="package://sr_description/hand/model/knuckle.dae" scale="0.001 0.001 0.001"/>
      </geometry>
      <material name="LightGrey"/>
    </visual>
    <collision>
      <origin rpy="0 0 0" xyz="0 0 0"/>
      <geometry name="ffknuckle_collision_geom">
        <box size="0.005 0.005 0.005"/>
      </geometry>
    </collision>
  </link>
  <gazebo reference="ffknuckle">
    <sensor name="ffknuckle_contact_sensor" type="contact">
      <update_rate>100.0</update_rate>
      <contact>
        <collision>ffknuckle_collision_geom</collision>
      </contact>
      <plugin filename="libgazebo_ros_bumper.so" name="ffknuckle_gazebo_ros_bumper_controller">
        <alwaysOn>true</alwaysOn>
        <frameName>ffknuckle</frameName>
        <updateRate>100.0</updateRate>
        <bumperTopicName>ffknuckle_bumper</bumperTopicName>
      </plugin>
    </sensor>
    <material>Gazebo/Grey</material>
  </gazebo>
  <joint name="FFJ4" type="revolute">
    <parent link="palm"/>
    <child link="ffknuckle"/>
    <!--<origin xyz="0.033 0 0.095" rpy="0 0 0" />-->
    <origin rpy="0 0 0" xyz="0.033 0 0.095"/>
    <axis xyz="0 -1 0"/>
    <limit effort="10" lower="-0.3491" upper="0.3491" velocity="1.0"/>
    <dynamics damping="50.5"/>
  </joint>
  <transmission name="ffknuckle_transmission" type="sr_mechanism_model/SimpleTransmission">
    <actuator name="FFJ4"/>
    <joint name="FFJ4"/>
    <mechanicalReduction>1</mechanicalReduction>
    <motorTorqueConstant>1</motorTorqueConstant>
    <pulsesPerRevolution>90000</pulsesPerRevolution>
  </transmission>
  <link name="ffproximal">
    <inertial>
      <mass value="0.014"/>
      <origin xyz="0 0 0.0225"/>
      <inertia ixx="0.1" ixy="0.0" ixz="0.0" iyy="0.1" iyz="0.0" izz="0.0"/>
    </inertial>
    <visual>
      <origin rpy="0 0 0" xyz="0 0 0"/>
      <geometry name="proximal_visual">
        <mesh filename="package://sr_description/hand/model/F3.dae" scale="0.001 0.001 0.001"/>
      </geometry>
      <material name="Grey"/>
    </visual>
    <collision>
      <origin rpy="0 0 0 " xyz="0 0 0.025"/>
      <geometry name="proximal_collision_geom">
        <box size="0.008 0.008 0.04"/>
      </geometry>
    </collision>
  </link>
  <gazebo reference="ffproximal">
    <sensor name="ffproximal_contact_sensor" type="contact">
      <update_rate>100.0</update_rate>
      <contact>
        <collision>ffproximal_collision_geom</collision>
      </contact>
      <plugin filename="libgazebo_ros_bumper.so" name="ffproximal_gazebo_ros_bumper_controller">
        <alwaysOn>true</alwaysOn>
        <frameName>ffproximal</frameName>
        <updateRate>100.0</updateRate>
        <bumperTopicName>ffproximal_bumper</bumperTopicName>
      </plugin>
    </sensor>
    <material>Gazebo/Grey</material>
    <selfCollide>true</selfCollide>
  </gazebo>
  <joint name="FFJ3" type="revolute">
    <parent link="ffknuckle"/>
    <child link="ffproximal"/>
    <origin rpy="0 0 0" xyz="0 0 0"/>
    <axis xyz="1 0 0"/>
    <limit effort="10" lower="0" upper="1.57079632679" velocity="1.0"/>
    <dynamics damping="50.5"/>
  </joint>
  <transmission name="ffproximal_transmission" type="sr_mechanism_model/SimpleTransmission">
    <actuator name="FFJ3"/>
    <joint name="FFJ3"/>
    <mechanicalReduction>1</mechanicalReduction>
    <motorTorqueConstant>1</motorTorqueConstant>
    <pulsesPerRevolution>90000</pulsesPerRevolution>
  </transmission>
  <link name="ffmiddle">
    <inertial>
      <origin rpy="0 0 0" xyz="0 0 0.0125"/>
      <mass value="0.012"/>
      <inertia ixx="0.1" ixy="0.0" ixz="0.0" iyy="0.1" iyz="0.0" izz="0.0"/>
    </inertial>
    <visual>
      <origin rpy="0 0 0" xyz="0 0 0"/>
      <geometry name="ffmiddle_visual">
        <mesh filename="package://sr_description/hand/model/F2.dae" scale="0.001 0.001 0.001"/>
      </geometry>
      <material name="Grey"/>
    </visual>
    <collision>
      <origin rpy="0 0 0" xyz="0 0 0.0125"/>
      <geometry name="ffmiddle_collision_geom">
        <box size="0.008 0.008 0.015"/>
      </geometry>
    </collision>
  </link>
  <gazebo reference="ffmiddle">
    <sensor name="ffmiddle_contact_sensor" type="contact">
      <update_rate>100.0</update_rate>
      <contact>
        <collision>ffmiddle_collision_geom</collision>
      </contact>
      <plugin filename="libgazebo_ros_bumper.so" name="ffmiddle_gazebo_ros_bumper_controller">
        <alwaysOn>true</alwaysOn>
        <frameName>ffmiddle</frameName>
        <updateRate>100.0</updateRate>
        <bumperTopicName>ffmiddle_bumper</bumperTopicName>
      </plugin>
    </sensor>
    <material>Gazebo/Grey</material>
    <selfCollide>true</selfCollide>
  </gazebo>
  <joint name="FFJ2" type="revolute">
    <parent link="ffproximal"/>
    <child link="ffmiddle"/>
    <origin rpy="0 0 0" xyz="0 0 0.045"/>
    <axis xyz="1 0 0"/>
    <limit effort="10" lower="0" upper="1.57079632679" velocity="1.0"/>
    <dynamics damping="50.5"/>
  </joint>
  <transmission name="ffmiddle_transmission" type="sr_mechanism_model/J0Transmission">
    <actuator name="FFJ0"/>
    <joint1 name="FFJ1"/>
    <joint2 name="FFJ2"/>
    <mechanicalReduction>1</mechanicalReduction>
    <motorTorqueConstant>1</motorTorqueConstant>
    <pulsesPerRevolution>90000</pulsesPerRevolution>
  </transmission>
  <link name="ffdistal">
    <inertial>
      <mass value="0.010"/>
      <origin xyz="0 0 0.013"/>
      <inertia ixx="0.1" ixy="0.0" ixz="0.0" iyy="0.1" iyz="0.0" izz="0.0"/>
    </inertial>
    <visual>
      <origin rpy="0 0 0" xyz="0 0 0"/>
      <geometry name="ffdistal_visual">
        <mesh filename="package://sr_description/hand/model/F1.dae" scale="0.001 0.001 0.001"/>
      </geometry>
      <material name="Grey"/>
    </visual>
    <collision>
      <origin rpy="0 0 0" xyz="0 0 0"/>
      <geometry name="ffdistal_collision_geom">
        <mesh filename="package://sr_description/hand/model/F1.dae" scale="0.001 0.001 0.001"/>
      </geometry>
    </collision>
  </link>
  <gazebo reference="ffdistal">
    <sensor name="ffdistal_contact_sensor" type="contact">
      <update_rate>100.0</update_rate>
      <contact>
        <collision>ffdistal_collision_geom</collision>
      </contact>
      <plugin filename="libgazebo_ros_bumper.so" name="ffdistal_gazebo_ros_bumper_controller">
        <alwaysOn>true</alwaysOn>
        <frameName>ffdistal</frameName>
        <updateRate>100.0</updateRate>
        <bumperTopicName>ffdistal_bumper</bumperTopicName>
      </plugin>
    </sensor>
    <mu1 value="500.0"/>
    <mu2 value="500.0"/>
    <kp value="10000000.0"/>
    <kd value="1.0"/>
    <material>Gazebo/Grey</material>
    <selfCollide>true</selfCollide>
  </gazebo>
  <joint name="FFJ1" type="revolute">
    <parent link="ffmiddle"/>
    <child link="ffdistal"/>
    <origin rpy="0 0 0" xyz="0 0 0.025"/>
    <axis xyz="1 0 0"/>
    <limit effort="10" lower="0" upper="1.57079632679" velocity="1.0"/>
    <dynamics damping="50.5"/>
  </joint>
  <link name="fftip">
    <inertial>
      <mass value="0.001"/>
      <inertia ixx="0.0" ixy="0.0" ixz="0.0" iyy="0.0" iyz="0.0" izz="0.0"/>
    </inertial>
  </link>
  <joint name="FFtip" type="fixed">
    <parent link="ffdistal"/>
    <child link="fftip"/>
    <origin rpy="0 0 0" xyz="0 0 0.026"/>
  </joint>
  <link name="mfknuckle">
    <inertial>
      <origin rpy="0 0 0" xyz="0 0 0"/>
      <!--<insert_block name="origin" /> -->
      <mass value="0.008"/>
      <inertia ixx="0.0" ixy="0.0" ixz="0.0" iyy="0.1" iyz="0.0" izz="0.0"/>
    </inertial>
    <visual>
      <origin rpy="0 0 0" xyz="0 0 0.0005"/>
      <geometry name="mfknuckle_visual">
        <mesh filename="package://sr_description/hand/model/knuckle.dae" scale="0.001 0.001 0.001"/>
      </geometry>
      <material name="LightGrey"/>
    </visual>
    <collision>
      <origin rpy="0 0 0" xyz="0 0 0"/>
      <geometry name="mfknuckle_collision_geom">
        <box size="0.005 0.005 0.005"/>
      </geometry>
    </collision>
  </link>
  <gazebo reference="mfknuckle">
    <sensor name="mfknuckle_contact_sensor" type="contact">
      <update_rate>100.0</update_rate>
      <contact>
        <collision>mfknuckle_collision_geom</collision>
      </contact>
      <plugin filename="libgazebo_ros_bumper.so" name="mfknuckle_gazebo_ros_bumper_controller">
        <alwaysOn>true</alwaysOn>
        <frameName>mfknuckle</frameName>
        <updateRate>100.0</updateRate>
        <bumperTopicName>mfknuckle_bumper</bumperTopicName>
      </plugin>
    </sensor>
    <material>Gazebo/Grey</material>
  </gazebo>
  <joint name="MFJ4" type="revolute">
    <parent link="palm"/>
    <child link="mfknuckle"/>
    <!--<origin xyz="0.033 0 0.095" rpy="0 0 0" />-->
    <origin rpy="0 0 0" xyz="0.011 0 0.099"/>
    <axis xyz="0 -1 0"/>
    <limit effort="10" lower="-0.3491" upper="0.3491" velocity="1.0"/>
    <dynamics damping="50.5"/>
  </joint>
  <transmission name="mfknuckle_transmission" type="sr_mechanism_model/SimpleTransmission">
    <actuator name="MFJ4"/>
    <joint name="MFJ4"/>
    <mechanicalReduction>1</mechanicalReduction>
    <motorTorqueConstant>1</motorTorqueConstant>
    <pulsesPerRevolution>90000</pulsesPerRevolution>
  </transmission>
  <link name="mfproximal">
    <inertial>
      <mass value="0.014"/>
      <origin xyz="0 0 0.0225"/>
      <inertia ixx="0.1" ixy="0.0" ixz="0.0" iyy="0.1" iyz="0.0" izz="0.0"/>
    </inertial>
    <visual>
      <origin rpy="0 0 0" xyz="0 0 0"/>
      <geometry name="proximal_visual">
        <mesh filename="package://sr_description/hand/model/F3.dae" scale="0.001 0.001 0.001"/>
      </geometry>
      <material name="Grey"/>
    </visual>
    <collision>
      <origin rpy="0 0 0 " xyz="0 0 0.025"/>
      <geometry name="proximal_collision_geom">
        <box size="0.008 0.008 0.04"/>
      </geometry>
    </collision>
  </link>
  <gazebo reference="mfproximal">
    <sensor name="mfproximal_contact_sensor" type="contact">
      <update_rate>100.0</update_rate>
      <contact>
        <collision>mfproximal_collision_geom</collision>
      </contact>
      <plugin filename="libgazebo_ros_bumper.so" name="mfproximal_gazebo_ros_bumper_controller">
        <alwaysOn>true</alwaysOn>
        <frameName>mfproximal</frameName>
        <updateRate>100.0</updateRate>
        <bumperTopicName>mfproximal_bumper</bumperTopicName>
      </plugin>
    </sensor>
    <material>Gazebo/Grey</material>
    <selfCollide>true</selfCollide>
  </gazebo>
  <joint name="MFJ3" type="revolute">
    <parent link="mfknuckle"/>
    <child link="mfproximal"/>
    <origin rpy="0 0 0" xyz="0 0 0"/>
    <axis xyz="1 0 0"/>
    <limit effort="10" lower="0" upper="1.57079632679" velocity="1.0"/>
    <dynamics damping="50.5"/>
  </joint>
  <transmission name="mfproximal_transmission" type="sr_mechanism_model/SimpleTransmission">
    <actuator name="MFJ3"/>
    <joint name="MFJ3"/>
    <mechanicalReduction>1</mechanicalReduction>
    <motorTorqueConstant>1</motorTorqueConstant>
    <pulsesPerRevolution>90000</pulsesPerRevolution>
  </transmission>
  <link name="mfmiddle">
    <inertial>
      <origin rpy="0 0 0" xyz="0 0 0.0125"/>
      <mass value="0.012"/>
      <inertia ixx="0.1" ixy="0.0" ixz="0.0" iyy="0.1" iyz="0.0" izz="0.0"/>
    </inertial>
    <visual>
      <origin rpy="0 0 0" xyz="0 0 0"/>
      <geometry name="mfmiddle_visual">
        <mesh filename="package://sr_description/hand/model/F2.dae" scale="0.001 0.001 0.001"/>
      </geometry>
      <material name="Grey"/>
    </visual>
    <collision>
      <origin rpy="0 0 0" xyz="0 0 0.0125"/>
      <geometry name="mfmiddle_collision_geom">
        <box size="0.008 0.008 0.015"/>
      </geometry>
    </collision>
  </link>
  <gazebo reference="mfmiddle">
    <sensor name="mfmiddle_contact_sensor" type="contact">
      <update_rate>100.0</update_rate>
      <contact>
        <collision>mfmiddle_collision_geom</collision>
      </contact>
      <plugin filename="libgazebo_ros_bumper.so" name="mfmiddle_gazebo_ros_bumper_controller">
        <alwaysOn>true</alwaysOn>
        <frameName>mfmiddle</frameName>
        <updateRate>100.0</updateRate>
        <bumperTopicName>mfmiddle_bumper</bumperTopicName>
      </plugin>
    </sensor>
    <material>Gazebo/Grey</material>
    <selfCollide>true</selfCollide>
  </gazebo>
  <joint name="MFJ2" type="revolute">
    <parent link="mfproximal"/>
    <child link="mfmiddle"/>
    <origin rpy="0 0 0" xyz="0 0 0.045"/>
    <axis xyz="1 0 0"/>
    <limit effort="10" lower="0" upper="1.57079632679" velocity="1.0"/>
    <dynamics damping="50.5"/>
  </joint>
  <transmission name="mfmiddle_transmission" type="sr_mechanism_model/J0Transmission">
    <actuator name="MFJ0"/>
    <joint1 name="MFJ1"/>
    <joint2 name="MFJ2"/>
    <mechanicalReduction>1</mechanicalReduction>
    <motorTorqueConstant>1</motorTorqueConstant>
    <pulsesPerRevolution>90000</pulsesPerRevolution>
  </transmission>
  <link name="mfdistal">
    <inertial>
      <mass value="0.010"/>
      <origin xyz="0 0 0.013"/>
      <inertia ixx="0.1" ixy="0.0" ixz="0.0" iyy="0.1" iyz="0.0" izz="0.0"/>
    </inertial>
    <visual>
      <origin rpy="0 0 0" xyz="0 0 0"/>
      <geometry name="mfdistal_visual">
        <mesh filename="package://sr_description/hand/model/F1.dae" scale="0.001 0.001 0.001"/>
      </geometry>
      <material name="Grey"/>
    </visual>
    <collision>
      <origin rpy="0 0 0" xyz="0 0 0"/>
      <geometry name="mfdistal_collision_geom">
        <mesh filename="package://sr_description/hand/model/F1.dae" scale="0.001 0.001 0.001"/>
      </geometry>
    </collision>
  </link>
  <gazebo reference="mfdistal">
    <sensor name="mfdistal_contact_sensor" type="contact">
      <update_rate>100.0</update_rate>
      <contact>
        <collision>mfdistal_collision_geom</collision>
      </contact>
      <plugin filename="libgazebo_ros_bumper.so" name="mfdistal_gazebo_ros_bumper_controller">
        <alwaysOn>true</alwaysOn>
        <frameName>mfdistal</frameName>
        <updateRate>100.0</updateRate>
        <bumperTopicName>mfdistal_bumper</bumperTopicName>
      </plugin>
    </sensor>
    <mu1 value="500.0"/>
    <mu2 value="500.0"/>
    <kp value="10000000.0"/>
    <kd value="1.0"/>
    <material>Gazebo/Grey</material>
    <selfCollide>true</selfCollide>
  </gazebo>
  <joint name="MFJ1" type="revolute">
    <parent link="mfmiddle"/>
    <child link="mfdistal"/>
    <origin rpy="0 0 0" xyz="0 0 0.025"/>
    <axis xyz="1 0 0"/>
    <limit effort="10" lower="0" upper="1.57079632679" velocity="1.0"/>
    <dynamics damping="50.5"/>
  </joint>
  <link name="mftip">
    <inertial>
      <mass value="0.001"/>
      <inertia ixx="0.0" ixy="0.0" ixz="0.0" iyy="0.0" iyz="0.0" izz="0.0"/>
    </inertial>
  </link>
  <joint name="MFtip" type="fixed">
    <parent link="mfdistal"/>
    <child link="mftip"/>
    <origin rpy="0 0 0" xyz="0 0 0.026"/>
  </joint>
  <link name="rfknuckle">
    <inertial>
      <origin rpy="0 0 0" xyz="0 0 0"/>
      <!--<insert_block name="origin" /> -->
      <mass value="0.008"/>
      <inertia ixx="0.0" ixy="0.0" ixz="0.0" iyy="0.1" iyz="0.0" izz="0.0"/>
    </inertial>
    <visual>
      <origin rpy="0 0 0" xyz="0 0 0.0005"/>
      <geometry name="rfknuckle_visual">
        <mesh filename="package://sr_description/hand/model/knuckle.dae" scale="0.001 0.001 0.001"/>
      </geometry>
      <material name="LightGrey"/>
    </visual>
    <collision>
      <origin rpy="0 0 0" xyz="0 0 0"/>
      <geometry name="rfknuckle_collision_geom">
        <box size="0.005 0.005 0.005"/>
      </geometry>
    </collision>
  </link>
  <gazebo reference="rfknuckle">
    <sensor name="rfknuckle_contact_sensor" type="contact">
      <update_rate>100.0</update_rate>
      <contact>
        <collision>rfknuckle_collision_geom</collision>
      </contact>
      <plugin filename="libgazebo_ros_bumper.so" name="rfknuckle_gazebo_ros_bumper_controller">
        <alwaysOn>true</alwaysOn>
        <frameName>rfknuckle</frameName>
        <updateRate>100.0</updateRate>
        <bumperTopicName>rfknuckle_bumper</bumperTopicName>
      </plugin>
    </sensor>
    <material>Gazebo/Grey</material>
  </gazebo>
  <joint name="RFJ4" type="revolute">
    <parent link="palm"/>
    <child link="rfknuckle"/>
    <!--<origin xyz="0.033 0 0.095" rpy="0 0 0" />-->
    <origin rpy="0 0 0" xyz="-0.011 0 0.095"/>
    <axis xyz="0 1 0"/>
    <limit effort="10" lower="-0.3491" upper="0.3491" velocity="1.0"/>
    <dynamics damping="50.5"/>
  </joint>
  <transmission name="rfknuckle_transmission" type="sr_mechanism_model/SimpleTransmission">
    <actuator name="RFJ4"/>
    <joint name="RFJ4"/>
    <mechanicalReduction>1</mechanicalReduction>
    <motorTorqueConstant>1</motorTorqueConstant>
    <pulsesPerRevolution>90000</pulsesPerRevolution>
  </transmission>
  <link name="rfproximal">
    <inertial>
      <mass value="0.014"/>
      <origin xyz="0 0 0.0225"/>
      <inertia ixx="0.1" ixy="0.0" ixz="0.0" iyy="0.1" iyz="0.0" izz="0.0"/>
    </inertial>
    <visual>
      <origin rpy="0 0 0" xyz="0 0 0"/>
      <geometry name="proximal_visual">
        <mesh filename="package://sr_description/hand/model/F3.dae" scale="0.001 0.001 0.001"/>
      </geometry>
      <material name="Grey"/>
    </visual>
    <collision>
      <origin rpy="0 0 0 " xyz="0 0 0.025"/>
      <geometry name="proximal_collision_geom">
        <box size="0.008 0.008 0.04"/>
      </geometry>
    </collision>
  </link>
  <gazebo reference="rfproximal">
    <sensor name="rfproximal_contact_sensor" type="contact">
      <update_rate>100.0</update_rate>
      <contact>
        <collision>rfproximal_collision_geom</collision>
      </contact>
      <plugin filename="libgazebo_ros_bumper.so" name="rfproximal_gazebo_ros_bumper_controller">
        <alwaysOn>true</alwaysOn>
        <frameName>rfproximal</frameName>
        <updateRate>100.0</updateRate>
        <bumperTopicName>rfproximal_bumper</bumperTopicName>
      </plugin>
    </sensor>
    <material>Gazebo/Grey</material>
    <selfCollide>true</selfCollide>
  </gazebo>
  <joint name="RFJ3" type="revolute">
    <parent link="rfknuckle"/>
    <child link="rfproximal"/>
    <origin rpy="0 0 0" xyz="0 0 0"/>
    <axis xyz="1 0 0"/>
    <limit effort="10" lower="0" upper="1.57079632679" velocity="1.0"/>
    <dynamics damping="50.5"/>
  </joint>
  <transmission name="rfproximal_transmission" type="sr_mechanism_model/SimpleTransmission">
    <actuator name="RFJ3"/>
    <joint name="RFJ3"/>
    <mechanicalReduction>1</mechanicalReduction>
    <motorTorqueConstant>1</motorTorqueConstant>
    <pulsesPerRevolution>90000</pulsesPerRevolution>
  </transmission>
  <link name="rfmiddle">
    <inertial>
      <origin rpy="0 0 0" xyz="0 0 0.0125"/>
      <mass value="0.012"/>
      <inertia ixx="0.1" ixy="0.0" ixz="0.0" iyy="0.1" iyz="0.0" izz="0.0"/>
    </inertial>
    <visual>
      <origin rpy="0 0 0" xyz="0 0 0"/>
      <geometry name="rfmiddle_visual">
        <mesh filename="package://sr_description/hand/model/F2.dae" scale="0.001 0.001 0.001"/>
      </geometry>
      <material name="Grey"/>
    </visual>
    <collision>
      <origin rpy="0 0 0" xyz="0 0 0.0125"/>
      <geometry name="rfmiddle_collision_geom">
        <box size="0.008 0.008 0.015"/>
      </geometry>
    </collision>
  </link>
  <gazebo reference="rfmiddle">
    <sensor name="rfmiddle_contact_sensor" type="contact">
      <update_rate>100.0</update_rate>
      <contact>
        <collision>rfmiddle_collision_geom</collision>
      </contact>
      <plugin filename="libgazebo_ros_bumper.so" name="rfmiddle_gazebo_ros_bumper_controller">
        <alwaysOn>true</alwaysOn>
        <frameName>rfmiddle</frameName>
        <updateRate>100.0</updateRate>
        <bumperTopicName>rfmiddle_bumper</bumperTopicName>
      </plugin>
    </sensor>
    <material>Gazebo/Grey</material>
    <selfCollide>true</selfCollide>
  </gazebo>
  <joint name="RFJ2" type="revolute">
    <parent link="rfproximal"/>
    <child link="rfmiddle"/>
    <origin rpy="0 0 0" xyz="0 0 0.045"/>
    <axis xyz="1 0 0"/>
    <limit effort="10" lower="0" upper="1.57079632679" velocity="1.0"/>
    <dynamics damping="50.5"/>
  </joint>
  <transmission name="rfmiddle_transmission" type="sr_mechanism_model/J0Transmission">
    <actuator name="RFJ0"/>
    <joint1 name="RFJ1"/>
    <joint2 name="RFJ2"/>
    <mechanicalReduction>1</mechanicalReduction>
    <motorTorqueConstant>1</motorTorqueConstant>
    <pulsesPerRevolution>90000</pulsesPerRevolution>
  </transmission>
  <link name="rfdistal">
    <inertial>
      <mass value="0.010"/>
      <origin xyz="0 0 0.013"/>
      <inertia ixx="0.1" ixy="0.0" ixz="0.0" iyy="0.1" iyz="0.0" izz="0.0"/>
    </inertial>
    <visual>
      <origin rpy="0 0 0" xyz="0 0 0"/>
      <geometry name="rfdistal_visual">
        <mesh filename="package://sr_description/hand/model/F1.dae" scale="0.001 0.001 0.001"/>
      </geometry>
      <material name="Grey"/>
    </visual>
    <collision>
      <origin rpy="0 0 0" xyz="0 0 0"/>
      <geometry name="rfdistal_collision_geom">
        <mesh filename="package://sr_description/hand/model/F1.dae" scale="0.001 0.001 0.001"/>
      </geometry>
    </collision>
  </link>
  <gazebo reference="rfdistal">
    <sensor name="rfdistal_contact_sensor" type="contact">
      <update_rate>100.0</update_rate>
      <contact>
        <collision>rfdistal_collision_geom</collision>
      </contact>
      <plugin filename="libgazebo_ros_bumper.so" name="rfdistal_gazebo_ros_bumper_controller">
        <alwaysOn>true</alwaysOn>
        <frameName>rfdistal</frameName>
        <updateRate>100.0</updateRate>
        <bumperTopicName>rfdistal_bumper</bumperTopicName>
      </plugin>
    </sensor>
    <mu1 value="500.0"/>
    <mu2 value="500.0"/>
    <kp value="10000000.0"/>
    <kd value="1.0"/>
    <material>Gazebo/Grey</material>
    <selfCollide>true</selfCollide>
  </gazebo>
  <joint name="RFJ1" type="revolute">
    <parent link="rfmiddle"/>
    <child link="rfdistal"/>
    <origin rpy="0 0 0" xyz="0 0 0.025"/>
    <axis xyz="1 0 0"/>
    <limit effort="10" lower="0" upper="1.57079632679" velocity="1.0"/>
    <dynamics damping="50.5"/>
  </joint>
  <link name="rftip">
    <inertial>
      <mass value="0.001"/>
      <inertia ixx="0.0" ixy="0.0" ixz="0.0" iyy="0.0" iyz="0.0" izz="0.0"/>
    </inertial>
  </link>
  <joint name="RFtip" type="fixed">
    <parent link="rfdistal"/>
    <child link="rftip"/>
    <origin rpy="0 0 0" xyz="0 0 0.026"/>
  </joint>
  <link name="lfmetacarpal">
    <inertial>
      <origin rpy="0 0 0" xyz="0 0 0.04"/>
      <mass value="0.075"/>
      <inertia ixx="0.1" ixy="0.0" ixz="0.0" iyy="0.1" iyz="0.0" izz="0.1"/>
    </inertial>
    <visual>
      <origin rpy="0 0 0" xyz="0 0 0"/>
      <geometry name="lfmetacarpal_visual">
        <mesh filename="package://sr_description/hand/model/lfmetacarpal.dae" scale="0.001 0.001 0.001"/>
      </geometry>
      <material name="Grey"/>
    </visual>
    <collision>
      <origin rpy="0 0 0" xyz="0 0 0.04"/>
      <geometry name="lfmetacarpal_collision_geom">
        <box size="0.008 0.008 0.03"/>
      </geometry>
    </collision>
  </link>
  <gazebo reference="lfmetacarpal">
    <sensor name="lfmetacarpal_contact_sensor" type="contact">
      <update_rate>100.0</update_rate>
      <contact>
        <collision>lfmetacarpal_collision_geom</collision>
      </contact>
      <plugin filename="libgazebo_ros_bumper.so" name="lfmetacarpal_gazebo_ros_bumper_controller">
        <alwaysOn>true</alwaysOn>
        <frameName>lfmetacarpal</frameName>
        <updateRate>100.0</updateRate>
        <bumperTopicName>lfmetacarpal_bumper</bumperTopicName>
      </plugin>
    </sensor>
    <material>Gazebo/Grey</material>
  </gazebo>
  <joint name="LFJ5" type="revolute">
    <parent link="palm"/>
    <child link="lfmetacarpal"/>
    <origin rpy="0 0 0" xyz="-0.033 0 0.02071"/>
    <axis xyz="0.573576436 0 0.819152044"/>
    <limit effort="10" lower="0" upper="0.785398163" velocity="1.0"/>
    <dynamics damping="50.5"/>
  </joint>
  <transmission name="lfmetacarpal_transmission" type="sr_mechanism_model/SimpleTransmission">
    <actuator name="LFJ5"/>
    <joint name="LFJ5"/>
    <mechanicalReduction>1</mechanicalReduction>
    <motorTorqueConstant>1</motorTorqueConstant>
    <pulsesPerRevolution>90000</pulsesPerRevolution>
  </transmission>
  <link name="lfknuckle">
    <inertial>
      <origin rpy="0 0 0" xyz="0 0 0"/>
      <!--<insert_block name="origin" /> -->
      <mass value="0.008"/>
      <inertia ixx="0.0" ixy="0.0" ixz="0.0" iyy="0.1" iyz="0.0" izz="0.0"/>
    </inertial>
    <visual>
      <origin rpy="0 0 0" xyz="0 0 0.0005"/>
      <geometry name="lfknuckle_visual">
        <mesh filename="package://sr_description/hand/model/knuckle.dae" scale="0.001 0.001 0.001"/>
      </geometry>
      <material name="LightGrey"/>
    </visual>
    <collision>
      <origin rpy="0 0 0" xyz="0 0 0"/>
      <geometry name="lfknuckle_collision_geom">
        <box size="0.005 0.005 0.005"/>
      </geometry>
    </collision>
  </link>
  <gazebo reference="lfknuckle">
    <sensor name="lfknuckle_contact_sensor" type="contact">
      <update_rate>100.0</update_rate>
      <contact>
        <collision>lfknuckle_collision_geom</collision>
      </contact>
      <plugin filename="libgazebo_ros_bumper.so" name="lfknuckle_gazebo_ros_bumper_controller">
        <alwaysOn>true</alwaysOn>
        <frameName>lfknuckle</frameName>
        <updateRate>100.0</updateRate>
        <bumperTopicName>lfknuckle_bumper</bumperTopicName>
      </plugin>
    </sensor>
    <material>Gazebo/Grey</material>
  </gazebo>
  <joint name="LFJ4" type="revolute">
    <parent link="lfmetacarpal"/>
    <child link="lfknuckle"/>
    <!--<origin xyz="0.033 0 0.095" rpy="0 0 0" />-->
    <origin rpy="0 0 0" xyz="0 0 0.06579"/>
    <axis xyz="0 1 0"/>
    <limit effort="10" lower="-0.3491" upper="0.3491" velocity="1.0"/>
    <dynamics damping="50.5"/>
  </joint>
  <transmission name="lfknuckle_transmission" type="sr_mechanism_model/SimpleTransmission">
    <actuator name="LFJ4"/>
    <joint name="LFJ4"/>
    <mechanicalReduction>1</mechanicalReduction>
    <motorTorqueConstant>1</motorTorqueConstant>
    <pulsesPerRevolution>90000</pulsesPerRevolution>
  </transmission>
  <link name="lfproximal">
    <inertial>
      <mass value="0.014"/>
      <origin xyz="0 0 0.0225"/>
      <inertia ixx="0.1" ixy="0.0" ixz="0.0" iyy="0.1" iyz="0.0" izz="0.0"/>
    </inertial>
    <visual>
      <origin rpy="0 0 0" xyz="0 0 0"/>
      <geometry name="proximal_visual">
        <mesh filename="package://sr_description/hand/model/F3.dae" scale="0.001 0.001 0.001"/>
      </geometry>
      <material name="Grey"/>
    </visual>
    <collision>
      <origin rpy="0 0 0 " xyz="0 0 0.025"/>
      <geometry name="proximal_collision_geom">
        <box size="0.008 0.008 0.04"/>
      </geometry>
    </collision>
  </link>
  <gazebo reference="lfproximal">
    <sensor name="lfproximal_contact_sensor" type="contact">
      <update_rate>100.0</update_rate>
      <contact>
        <collision>lfproximal_collision_geom</collision>
      </contact>
      <plugin filename="libgazebo_ros_bumper.so" name="lfproximal_gazebo_ros_bumper_controller">
        <alwaysOn>true</alwaysOn>
        <frameName>lfproximal</frameName>
        <updateRate>100.0</updateRate>
        <bumperTopicName>lfproximal_bumper</bumperTopicName>
      </plugin>
    </sensor>
    <material>Gazebo/Grey</material>
    <selfCollide>true</selfCollide>
  </gazebo>
  <joint name="LFJ3" type="revolute">
    <parent link="lfknuckle"/>
    <child link="lfproximal"/>
    <origin rpy="0 0 0" xyz="0 0 0"/>
    <axis xyz="1 0 0"/>
    <limit effort="10" lower="0" upper="1.57079632679" velocity="1.0"/>
    <dynamics damping="50.5"/>
  </joint>
  <transmission name="lfproximal_transmission" type="sr_mechanism_model/SimpleTransmission">
    <actuator name="LFJ3"/>
    <joint name="LFJ3"/>
    <mechanicalReduction>1</mechanicalReduction>
    <motorTorqueConstant>1</motorTorqueConstant>
    <pulsesPerRevolution>90000</pulsesPerRevolution>
  </transmission>
  <link name="lfmiddle">
    <inertial>
      <origin rpy="0 0 0" xyz="0 0 0.0125"/>
      <mass value="0.012"/>
      <inertia ixx="0.1" ixy="0.0" ixz="0.0" iyy="0.1" iyz="0.0" izz="0.0"/>
    </inertial>
    <visual>
      <origin rpy="0 0 0" xyz="0 0 0"/>
      <geometry name="lfmiddle_visual">
        <mesh filename="package://sr_description/hand/model/F2.dae" scale="0.001 0.001 0.001"/>
      </geometry>
      <material name="Grey"/>
    </visual>
    <collision>
      <origin rpy="0 0 0" xyz="0 0 0.0125"/>
      <geometry name="lfmiddle_collision_geom">
        <box size="0.008 0.008 0.015"/>
      </geometry>
    </collision>
  </link>
  <gazebo reference="lfmiddle">
    <sensor name="lfmiddle_contact_sensor" type="contact">
      <update_rate>100.0</update_rate>
      <contact>
        <collision>lfmiddle_collision_geom</collision>
      </contact>
      <plugin filename="libgazebo_ros_bumper.so" name="lfmiddle_gazebo_ros_bumper_controller">
        <alwaysOn>true</alwaysOn>
        <frameName>lfmiddle</frameName>
        <updateRate>100.0</updateRate>
        <bumperTopicName>lfmiddle_bumper</bumperTopicName>
      </plugin>
    </sensor>
    <material>Gazebo/Grey</material>
    <selfCollide>true</selfCollide>
  </gazebo>
  <joint name="LFJ2" type="revolute">
    <parent link="lfproximal"/>
    <child link="lfmiddle"/>
    <origin rpy="0 0 0" xyz="0 0 0.045"/>
    <axis xyz="1 0 0"/>
    <limit effort="10" lower="0" upper="1.57079632679" velocity="1.0"/>
    <dynamics damping="50.5"/>
  </joint>
  <transmission name="lfmiddle_transmission" type="sr_mechanism_model/J0Transmission">
    <actuator name="LFJ0"/>
    <joint1 name="LFJ1"/>
    <joint2 name="LFJ2"/>
    <mechanicalReduction>1</mechanicalReduction>
    <motorTorqueConstant>1</motorTorqueConstant>
    <pulsesPerRevolution>90000</pulsesPerRevolution>
  </transmission>
  <link name="lfdistal">
    <inertial>
      <mass value="0.010"/>
      <origin xyz="0 0 0.013"/>
      <inertia ixx="0.1" ixy="0.0" ixz="0.0" iyy="0.1" iyz="0.0" izz="0.0"/>
    </inertial>
    <visual>
      <origin rpy="0 0 0" xyz="0 0 0"/>
      <geometry name="lfdistal_visual">
        <mesh filename="package://sr_description/hand/model/F1.dae" scale="0.001 0.001 0.001"/>
      </geometry>
      <material name="Grey"/>
    </visual>
    <collision>
      <origin rpy="0 0 0" xyz="0 0 0"/>
      <geometry name="lfdistal_collision_geom">
        <mesh filename="package://sr_description/hand/model/F1.dae" scale="0.001 0.001 0.001"/>
      </geometry>
    </collision>
  </link>
  <gazebo reference="lfdistal">
    <sensor name="lfdistal_contact_sensor" type="contact">
      <update_rate>100.0</update_rate>
      <contact>
        <collision>lfdistal_collision_geom</collision>
      </contact>
      <plugin filename="libgazebo_ros_bumper.so" name="lfdistal_gazebo_ros_bumper_controller">
        <alwaysOn>true</alwaysOn>
        <frameName>lfdistal</frameName>
        <updateRate>100.0</updateRate>
        <bumperTopicName>lfdistal_bumper</bumperTopicName>
      </plugin>
    </sensor>
    <mu1 value="500.0"/>
    <mu2 value="500.0"/>
    <kp value="10000000.0"/>
    <kd value="1.0"/>
    <material>Gazebo/Grey</material>
    <selfCollide>true</selfCollide>
  </gazebo>
  <joint name="LFJ1" type="revolute">
    <parent link="lfmiddle"/>
    <child link="lfdistal"/>
    <origin rpy="0 0 0" xyz="0 0 0.025"/>
    <axis xyz="1 0 0"/>
    <limit effort="10" lower="0" upper="1.57079632679" velocity="1.0"/>
    <dynamics damping="50.5"/>
  </joint>
  <link name="lftip">
    <inertial>
      <mass value="0.001"/>
      <inertia ixx="0.0" ixy="0.0" ixz="0.0" iyy="0.0" iyz="0.0" izz="0.0"/>
    </inertial>
  </link>
  <joint name="LFtip" type="fixed">
    <parent link="lfdistal"/>
    <child link="lftip"/>
    <origin rpy="0 0 0" xyz="0 0 0.026"/>
  </joint>
  <link name="thbase">
    <inertial>
      <mass value="0.010"/>
      <origin rpy="0 0 0" xyz="0 0 0"/>
      <inertia ixx="0.0" ixy="0.0" ixz="0.0" iyy="0.0" iyz="0.0" izz="0.1"/>
    </inertial>
    <visual>
      <origin rpy="0 0 0" xyz="0 0 0"/>
      <geometry name="thbase_visual">
        <box size="0.001 0.001 0.001"/>
      </geometry>
      <material name="shadow_thbase_material">
        <color rgba="0.5 0.5 0.5 1.0"/>
      </material>
    </visual>
    <collision>
      <origin rpy="0 0 0 " xyz="0 0 0"/>
      <geometry name="thbase_collision_geom">
        <box size="0.001 0.001 0.001"/>
      </geometry>
    </collision>
  </link>
  <gazebo reference="thbase">
    <sensor name="thbase_contact_sensor" type="contact">
      <update_rate>100.0</update_rate>
      <contact>
        <collision>thbase_collision_geom</collision>
      </contact>
      <plugin filename="libgazebo_ros_bumper.so" name="thbase_gazebo_ros_bumper_controller">
        <alwaysOn>true</alwaysOn>
        <frameName>thbase</frameName>
        <updateRate>100.0</updateRate>
        <bumperTopicName>thbase_bumper</bumperTopicName>
      </plugin>
    </sensor>
    <material>Gazebo/Grey</material>
  </gazebo>
  <joint name="THJ5" type="revolute">
    <parent link="palm"/>
    <child link="thbase"/>
    <origin rpy="0 0.785398163397 0" xyz="0.034 -0.0085 0.029"/>
    <axis xyz="0 0 -1.0"/>
    <limit effort="10" lower="-1.047" upper="1.047" velocity="1.0"/>
    <dynamics damping="50.5"/>
  </joint>
  <transmission name="thbase_transmission" type="sr_mechanism_model/SimpleTransmission">
    <actuator name="THJ5"/>
    <joint name="THJ5"/>
    <mechanicalReduction>1</mechanicalReduction>
    <motorTorqueConstant>1</motorTorqueConstant>
    <pulsesPerRevolution>90000</pulsesPerRevolution>
  </transmission>
  <link name="thproximal">
    <inertial>
      <mass value="0.016"/>
      <origin rpy="0 0 0" xyz="0 0 0.019"/>
      <inertia ixx="0.1" ixy="0.0" ixz="0.0" iyy="0.1" iyz="0.0" izz="0.1"/>
    </inertial>
    <visual>
      <origin rpy="0 0 0" xyz="0 0 0"/>
      <geometry name="thproximal_visual">
        <mesh filename="package://sr_description/hand/model/TH3_z.dae" scale="0.001 0.001 0.001"/>
      </geometry>
      <material name="shadow_thproximal_material">
        <color rgba="0.2 0.2 0.2 1.0"/>
      </material>
    </visual>
    <collision>
      <origin rpy="0 0 0" xyz="0 0 0.019"/>
      <geometry name="thproximal_collision_geom">
        <box size="0.008 0.008 0.020"/>
      </geometry>
    </collision>
  </link>
  <gazebo reference="thproximal">
    <sensor name="thproximal_contact_sensor" type="contact">
      <update_rate>100.0</update_rate>
      <contact>
        <collision>thproximal_collision_geom</collision>
      </contact>
      <plugin filename="libgazebo_ros_bumper.so" name="thproximal_gazebo_ros_bumper_controller">
        <alwaysOn>true</alwaysOn>
        <frameName>thproximal</frameName>
        <updateRate>100.0</updateRate>
        <bumperTopicName>thproximal_bumper</bumperTopicName>
      </plugin>
    </sensor>
    <material>Gazebo/Grey</material>
  </gazebo>
  <joint name="THJ4" type="revolute">
    <parent link="thbase"/>
    <child link="thproximal"/>
    <origin rpy="0 0 0" xyz="0 0 0"/>
    <axis xyz="1.0 0 0"/>
    <limit effort="10" lower="0" upper="1.309" velocity="1.0"/>
    <dynamics damping="50.5"/>
  </joint>
  <transmission name="thproximal_transmission" type="sr_mechanism_model/SimpleTransmission">
    <actuator name="THJ4"/>
    <joint name="THJ4"/>
    <mechanicalReduction>1</mechanicalReduction>
    <motorTorqueConstant>1</motorTorqueConstant>
    <pulsesPerRevolution>90000</pulsesPerRevolution>
  </transmission>
  <link name="thhub">
    <inertial>
      <mass value="0.002"/>
      <origin rpy="0 0 0" xyz="0 0 0"/>
      <inertia ixx="0.1" ixy="0.0" ixz="0.0" iyy="0.1" iyz="0.0" izz="0.1"/>
    </inertial>
    <visual>
      <origin rpy="0 0 0" xyz="0 0 0"/>
      <geometry name="thhub_visual">
        <box size="0.001 0.001 0.001"/>
      </geometry>
      <material name="shadow_thhub_material">
        <color rgba="0.7 0.7 0.7 1.0"/>
      </material>
    </visual>
    <collision>
      <origin rpy="0 0 0 " xyz="0 0 0"/>
      <geometry name="thhub_collision_geom">
        <box size="0.001 0.001 0.001"/>
      </geometry>
    </collision>
  </link>
  <gazebo reference="thhub">
    <sensor name="thhub_contact_sensor" type="contact">
      <update_rate>100.0</update_rate>
      <contact>
        <collision>thhub_collision_geom</collision>
      </contact>
      <plugin filename="libgazebo_ros_bumper.so" name="thhub_gazebo_ros_bumper_controller">
        <alwaysOn>true</alwaysOn>
        <frameName>thhub</frameName>
        <updateRate>100.0</updateRate>
        <bumperTopicName>thhub_bumper</bumperTopicName>
      </plugin>
    </sensor>
    <material>Gazebo/Grey</material>
  </gazebo>
  <joint name="THJ3" type="revolute">
    <parent link="thproximal"/>
    <child link="thhub"/>
    <origin rpy="0 0 0" xyz="0 0 0.038"/>
    <axis xyz="1 0 0"/>
    <limit effort="10" lower="-0.2618" upper="0.2618" velocity="1.0"/>
    <dynamics damping="50.5"/>
  </joint>
  <transmission name="thhub_transmission" type="sr_mechanism_model/SimpleTransmission">
    <actuator name="THJ3"/>
    <joint name="THJ3"/>
    <mechanicalReduction>1</mechanicalReduction>
    <motorTorqueConstant>1</motorTorqueConstant>
    <pulsesPerRevolution>90000</pulsesPerRevolution>
  </transmission>
  <link name="thmiddle">
    <inertial>
      <mass value="0.016"/>
      <origin rpy="0 0 0" xyz="0 0 0.016"/>
      <inertia ixx="0.1" ixy="0.0" ixz="0.0" iyy="0.1" iyz="0.0" izz="0.1"/>
    </inertial>
    <visual>
      <origin rpy="0 0 0" xyz="0 0 0"/>
      <geometry name="thmiddle_visual">
        <mesh filename="package://sr_description/hand/model/TH2_z.dae" scale="0.001 0.001 0.001"/>
      </geometry>
      <material name="shadow_thmiddle_material">
        <color rgba="0.2 0.2 0.2 1.0"/>
      </material>
    </visual>
    <collision>
      <origin rpy="0 0 0 " xyz="0 0 0.016"/>
      <geometry name="thmiddle_collision_geom">
        <box size="0.008 0.008 0.015"/>
      </geometry>
    </collision>
  </link>
  <gazebo reference="thmiddle">
    <sensor name="thmiddle_contact_sensor" type="contact">
      <update_rate>100.0</update_rate>
      <contact>
        <collision>thmiddle_collision_geom</collision>
      </contact>
      <plugin filename="libgazebo_ros_bumper.so" name="thmiddle_gazebo_ros_bumper_controller">
        <alwaysOn>true</alwaysOn>
        <frameName>thmiddle</frameName>
        <updateRate>100.0</updateRate>
        <bumperTopicName>thmiddle_bumper</bumperTopicName>
      </plugin>
    </sensor>
    <material>Gazebo/Grey</material>
  </gazebo>
  <joint name="THJ2" type="revolute">
    <parent link="thhub"/>
    <child link="thmiddle"/>
    <origin rpy="0 0 0" xyz="0 0 0"/>
    <axis xyz="0 -1 0"/>
    <limit effort="10" lower="-0.6981" upper="0.6981" velocity="1.0"/>
    <dynamics damping="50.5"/>
  </joint>
  <transmission name="thmiddle_transmission" type="sr_mechanism_model/SimpleTransmission">
    <actuator name="THJ2"/>
    <joint name="THJ2"/>
    <mechanicalReduction>1</mechanicalReduction>
    <motorTorqueConstant>1</motorTorqueConstant>
    <pulsesPerRevolution>90000</pulsesPerRevolution>
  </transmission>
  <link name="thdistal">
    <inertial>
      <mass value="0.016"/>
      <origin rpy="0 0 0" xyz="0 0 0.01375"/>
      <inertia ixx="0.1" ixy="0.0" ixz="0.0" iyy="0.1" iyz="0.0" izz="0.1"/>
    </inertial>
    <visual>
      <origin rpy="0 0 0" xyz="0 0 0"/>
      <geometry name="thdistal_visual">
        <mesh filename="package://sr_description/hand/model/TH1_z.dae" scale="0.001 0.001 0.001"/>
      </geometry>
      <material name="shadow_thmiddle_material">
        <color rgba="0.2 0.2 0.2 1.0"/>
      </material>
    </visual>
    <collision>
      <origin rpy="0 0 0 " xyz="0 0 0"/>
      <geometry name="thmiddle_collision_geom">
        <mesh filename="package://sr_description/hand/model/TH1_z.dae" scale="0.001 0.001 0.001"/>
        <!--	  <box size="0.015 0.015 0.015" /> -->
      </geometry>
    </collision>
  </link>
  <gazebo reference="thdistal">
    <sensor name="thdistal_contact_sensor" type="contact">
      <update_rate>100.0</update_rate>
      <contact>
        <collision>thdistal_collision_geom</collision>
      </contact>
      <plugin filename="libgazebo_ros_bumper.so" name="thdistal_gazebo_ros_bumper_controller">
        <alwaysOn>true</alwaysOn>
        <frameName>thdistal</frameName>
        <updateRate>100.0</updateRate>
        <bumperTopicName>thdistal_bumper</bumperTopicName>
      </plugin>
    </sensor>
    <material>Gazebo/Grey</material>
    <mu1 value="500.0"/>
    <mu2 value="500.0"/>
    <kp value="10000000.0"/>
    <kd value="1.0"/>
    <material>Gazebo/Grey</material>
    <selfCollide>true</selfCollide>
  </gazebo>
  <joint name="THJ1" type="revolute">
    <parent link="thmiddle"/>
    <child link="thdistal"/>
    <origin rpy="0 0 -1.570796327" xyz="0 0 0.032"/>
    <axis xyz="1 0 0"/>
    <limit effort="10" lower="0" upper="1.571" velocity="1.0"/>
    <dynamics damping="50.5"/>
  </joint>
  <link name="thtip">
    <inertial>
      <mass value="0.001"/>
      <inertia ixx="0.0" ixy="0.0" ixz="0.0" iyy="0.0" iyz="0.0" izz="0.0"/>
    </inertial>
  </link>
  <joint name="thtip" type="fixed">
    <parent link="thdistal"/>
    <child link="thtip"/>
    <origin rpy="0 0 0" xyz="0 0 0.0275"/>
  </joint>
  <transmission name="thdistal_transmission" type="sr_mechanism_model/SimpleTransmission">
    <actuator name="THJ1"/>
    <joint name="THJ1"/>
    <mechanicalReduction>1</mechanicalReduction>
    <motorTorqueConstant>1</motorTorqueConstant>
    <pulsesPerRevolution>90000</pulsesPerRevolution>
  </transmission>
</robot>
